Workbook

Sheet Cities
A1: No. | B1: ID | C1: List group | D1: Ancient region | E1: City (Latin alphabet) | F1: Greek name | G1: Other names | H1: Turkish name (town on the site) | I1: Modern status | J1: Site today | K1: Province (il) | L1: Present-day region | M1: District centre (ilçe) | N1: Provincial capital | O1: Turkish name comes from | P1: Latitude | Q1: Longitude | R1: Location | S1: Greek from (year; negative = BC) | T1: Date as shown | U1: Date basis | V1: Date precision | W1: Period | X1: How it became Greek | Y1: Founder | Z1: Founder group | AA1: Mother city | AB1: Earlier settlement | AC1: Evidence of earlier settlement | AD1: Pre-Greek name | AE1: Note on pre-Greek name | AF1: Evidence of city status | AG1: Later majority language (if not Greek) | AH1: Certainty | AI1: Note | AJ1: Sources | AK1: Pleiades | AL1: When first Greek (text) | AM1: Mixed city (†) | AN1: Turkish name reached Turkish through | AO1: Earlier settlement: evidence in detail | AP1: Earlier settlement: sources | AQ1: Earlier settlement: confidence
A2: 1 | B2: C001 | C2: Thrace | D2: Thrace | E2: Imbros | F2: Ἴμβρος | G2: Kastro (medieval capital) | H2: Kaleköy | I2: village on site | J2: Kaleköy (Gökçeada, Çanakkale) | K2: Çanakkale | L2: Marmara | O2: unrelated | P2: 40.2333 | Q2: 25.9008 | R2: secure | S2: -500 | T2: c. 500 BC | U2: first attestation as Greek city | V2: decade | W2: 2 Archaic (c. 760–481 BC) | X2: colony | Y2: Athenians under Miltiades (cleruchy) | Z2: colonists | AA2: Athens | AB2: yes | AC2: text | AE2: Herodotus (5.26) says Imbros was inhabited by 'Pelasgians' when Otanes took it c. 511 BC; no native name attested. The text refers to the island, not specifically to the Kastro site. | AF2: IACP (Imbros); ATL (Imbrioi); own coins (Hermes Imbramos) 4th c. BC; medieval Roman bishopric (later metropolis of Imbros) | AH2: secure | AI2: The ancient and medieval town was at Kastro/Kaleköy on the N coast. The island was surrendered to Mehmed II through Kritoboulos of Imbros, 1455/56. | AJ2: IACP (Imbros); Hdt. 5.26; 6.41; Pleiades 501438; Wikipedia: Imbros | AK2: 501438 | AL2: Athenian possession under Miltiades by c. 500-493 BC; Athenian cleruchy (re)organised c. 450 BC
A3: 2 | B3: C002 | C3: Thrace | D3: Thrace | E3: Elaeus | F3: Ἐλαιοῦς | G3: Elaious | I3: ruins only | J3: near Seddülbahir (Eceabat, Çanakkale) | K3: Çanakkale | L3: Marmara | P3: 40.0545 | Q3: 26.2233 | R3: secure | S3: -600 | T3: c. 600 BC | U3: archaeology | V3: century | W3: 2 Archaic (c. 760–481 BC) | X3: colony | Y3: Athenians under Phorbas (Ps.-Scymnus); Teos or an Ephesian, Hegesistratus, in other sources | Z3: colonists | AA3: Athens (disputed: Teos) | AB3: unknown | AE3: An Early Bronze Age (Troy I–II period) settlement mound lies under the so-called tumulus of Protesilaos at Karaağaç Tepe near Elaious (Schliemann; Demangel 1926); it is next to the Greek town rather than under it, so pre_settlement stays 'unknown'. | AF3: IACP (Thracian Chersonese); ATL; Hellenistic coins; Roman provincial coins (Commodus); fortified by Justinian | AH3: secure | AI3: The mother city is disputed: Athens (Ps.-Scymnus), Teos, or an Ephesian founder (Plutarch). The Protesilaos sanctuary was in its territory. | AJ3: IACP (Thracian Chersonese); Hdt. 9.116-120; Pleiades 501411; Wikipedia: Elaeus | AK3: 501411 | AL3: Archaic colony, c. 600 BC (necropolis excavated 1915-23 is Archaic); founders disputed | AO3: The town (Eski Hisarlık) has yielded only an Archaic-Hellenistic necropolis (French excavations 1915, 1920-23). The so-called tumulus of Protesilaos at Karaağaç Tepe is a Chalcolithic/EBA/LBA settlement mound (Demangel 1926; Özdoğan 1993), but it lies c. 2.5 km W of the town near Seddülbahir, beyond the same-site test. | AP3: Demangel, Le tumulus dit de Protésilas (1926); DEFC site 747; LuwianSiteAtlas site 87 (Özdoğan, IstMitt 43, 1993); Waiblinger, CRAI 1978; Pleiades 501411 | AQ3: low
A4: 3 | B4: C003 | C4: Thrace | D4: Thrace | E4: Alopeconnesus | F4: Ἀλωπεκόννησος | I4: lost/unlocated | J4: near Anafarta harbour / Suvla bay (Eceabat, Çanakkale) | K4: Çanakkale | L4: Marmara | P4: 40.3139 | Q4: 26.2495 | R4: approximate | S4: -600 | T4: c. 600 BC | U4: ancient foundation date | V4: period | W4: 2 Archaic (c. 760–481 BC) | X4: colony | Y4: Aeolians (Ps.-Scymnus; fox-oracle foundation story) | Z4: colonists | AA4: Aeolis (unspecified Aeolian city) | AB4: unknown | AF4: IACP (Thracian Chersonese); ATL (Delian League member); own coins 4th c. BC | AH4: secure | AI4: The site is placed at Anafarta harbour on the Aegean side of the peninsula, which is uncertain. Its colonists are also said to have taken part in founding Ainos. | AJ4: IACP (Thracian Chersonese); Pleiades 501345; Wikipedia: Alopeconnesus | AK4: 501345 | AL4: Aeolian colony of Archaic date (7th-6th c. BC); exact date unrecorded | AO4: Site unlocated; no evidence either way. | AP4: Pleiades 501345 | AQ4: high
A5: 4 | B5: C004 | C5: Thrace | D5: Thrace | E5: Limnae | F5: Λίμναι | I5: lost/unlocated | J5: W side of the peninsula N of Eceabat (Eceabat, Çanakkale) | K5: Çanakkale | L5: Marmara | P5: 40.2706 | Q5: 26.2727 | R5: approximate | S5: -600 | T5: c. 600 BC | U5: ancient foundation date | V5: period | W5: 2 Archaic (c. 760–481 BC) | X5: colony | Y5: Miletus | Z5: colonists | AA5: Miletus | AB5: unknown | AF5: IACP (Thracian Chersonese); ATL (Limnaioi) | AH5: probable | AI5: Strabo (7 fr.) calls it a Milesian foundation. The site is not identified; the Barrington Atlas places it approximately. | AJ5: IACP (Thracian Chersonese); Strabo 7 fr. 51; Pleiades 501497 | AK5: 501497 | AL5: Milesian colony of Archaic date; exact date unrecorded | AO5: Site unlocated; no evidence either way. | AP5: Pleiades 501497; Strabo 7 fr. 51 | AQ5: high
A6: 5 | B6: C005 | C6: Thrace | D6: Thrace | E6: Madytus | F6: Μάδυτος | G6: Madytos; Maydos (Ottoman) | H6: Eceabat | I6: city/town on site | J6: Eceabat (Eceabat, Çanakkale) | K6: Çanakkale | L6: Marmara | M6: Eceabat | O6: unrelated | P6: 40.1847 | Q6: 26.3561 | R6: secure | S6: -650 | T6: c. 650 BC | U6: ancient foundation date | V6: century | W6: 2 Archaic (c. 760–481 BC) | X6: colony | Y6: Aeolians from Lesbos | Z6: colonists | AA6: Lesbos | AB6: yes | AC6: archaeology | AE6: The Madytos mound excavations at Eceabat found Early, Middle and Late Bronze Age levels below the Greek town; no pre-Greek name is attested. | AF6: IACP (Thracian Chersonese); ATL 445/4-421/0; own bronze coins 4th c. BC (ΜΑΔΥ); bishopric (787 'Madyta or Koila'; Notitiae 10th-14th c.) | AH6: secure | AI6: Ottoman Maydos continued the Greek name until 1928, when it was renamed Eceabat. Some sources add later Milesian/Klazomenian settlers. | AJ6: IACP (Thracian Chersonese); Pleiades 501503; Wikipedia: Madytus; TIB 12 | AK6: 501503 | AL6: Aeolian (Lesbian) colony, 7th c. BC
A7: 6 | B7: C006 | C7: Thrace | D7: Thrace | E7: Coela | F7: Κοῖλα | G7: Municipium Aelium Coela (Latin coins); Koila | I7: lost/unlocated | J7: Kilye bay N of Eceabat (Eceabat, Çanakkale) | K7: Çanakkale | L7: Marmara | P7: 40.2071 | Q7: 26.3676 | R7: approximate | S7: 125 | T7: c. AD 125 | U7: documented royal/imperial foundation | V7: period | W7: 5 Roman (30 BC – AD 329) | X7: Roman foundation | Y7: Hadrian (municipium Aelium) | Z7: Roman emperors to 330 | AB7: unknown | AF7: Roman provincial coins with Latin legends (Hadrian to 3rd c.); Hierocles (Europa); bishops 431, 458, 787 | AG7: Latin was the official language of the municipium (coins); Greek-speaking see by the 5th c. | AH7: probable | AI7: It was a harbour of the Chersonese before it became a municipium. In 787 the see is called 'Madyta or Koila', and from the 10th c. it is listed as Madytos. | AJ7: Pleiades 501471; Wikipedia: Coela; TIB 12 (Külzer 2008); Le Quien, Oriens Christianus | AK7: 501471 | AL7: made a Roman municipium by Hadrian (coins: Aelium Coela); bishop 431 | AO7: Site at Kilye bay not identified on the ground. The large Bronze Age mound of Maydos Kilisetepe lies in Eceabat itself, c. 3 km to the S, and belongs to Madytos, not Koila. | AP7: Pleiades 501471; hurriyetdailynews.com (Maydos Kilisetepe 2200 BC wall) | AQ7: medium
A8: 7 | B8: C007 | C8: Thrace | D8: Thrace | E8: Sestus | F8: Σηστός | G8: Sestos | I8: ruins only | J8: Akbaş, near Yalova village (Eceabat, Çanakkale) | K8: Çanakkale | L8: Marmara | P8: 40.2134 | Q8: 26.3893 | R8: secure | S8: -650 | T8: c. 650 BC | U8: ancient foundation date | V8: century | W8: 2 Archaic (c. 760–481 BC) | X8: colony | Y8: Aeolians from Lesbos | Z8: colonists | AA8: Lesbos | AB8: unknown | AF8: IACP (Thracian Chersonese); ATL; decree for Menas (OGIS 339, late 2nd c. BC); coins Hellenistic-Roman | AH8: secure | AI8: It was the main crossing point of the Hellespont (Xerxes' bridge, siege of 479 BC). Justinian fortified it, but it was not a late Roman see. | AJ8: IACP (Thracian Chersonese); Hdt. 9.114-118; OGIS 339; Pleiades 501609 | AK8: 501609 | AL8: Aeolian (Lesbian) colony, 7th c. BC | AO8: Rejected the proposed 'yes'. The LBA claim comes from a Turkish surface survey (Körpe, AST 33, 2016), relayed by the LuwianSiteAtlas, which does not count as evidence. Surface sherds are not stratified, and the city's location is itself uncertain (Barrington: 'Yalıkabat?'; Akbaş castle per others). Homer's listing of Sestos among the Trojan allies (Il. 2.836), which Isaac 1986 and Der Kleine Pauly take as a 'Thracian' Sestos, is epic tradition and not enough on its own (rule 5). I found no excavation evidence of pre-colonial levels in non-Turkish literature. | AP8: en./de.wikipedia.org/wiki/Sestos (citing Isaac 1986, 159-60; von Bredow, BNP; Danoff, KlP); Pleiades 501609 (BAtlas 51 G4, 'Yalikabat?'); Hom. Il. 2.835-6; Körpe 2016 not accessible (surface survey) | AQ8: medium
A9: 8 | B9: C008 | C9: Thrace | D9: Thrace | E9: Aegospotami | F9: Αἰγὸς ποταμοί | G9: Aigos Potamoi | I9: lost/unlocated | J9: coast S of Gelibolu (Gelibolu, Çanakkale) | K9: Çanakkale | L9: Marmara | P9: 40.3315 | Q9: 26.5994 | R9: approximate | S9: -405 | T9: c. 405 BC | U9: first attestation as Greek city | V9: decade | W9: 3 Classical (480–335 BC) | X9: Greek town grown into city | Y9: unknown | Z9: none (native town) | AB9: unknown | AF9: IACP (Thracian Chersonese); Ps.-Skylax 67; own coins 4th c. BC (goat type) | AH9: probable | AI9: It is known mainly for Lysander's victory of 405 BC. The town's site at the mouth of the 'Goat River' is not precisely located. | AJ9: IACP (Thracian Chersonese); Xen. Hell. 2.1; Pleiades 501336 | AK9: 501336 | AL9: attested as a polis at the battle of 405 BC; own coins 4th c. BC | AO9: Site unlocated; no evidence either way. | AP9: Pleiades 501336 | AQ9: high
A10: 9 | B10: C009 | C10: Thrace | D10: Thrace | E10: Crithote | F10: Κριθωτή | G10: Krithote | I10: lost/unlocated | J10: near Gelibolu (Gelibolu, Çanakkale) | K10: Çanakkale | L10: Marmara | P10: 40.4067 | Q10: 26.6517 | R10: approximate | S10: -555 | T10: c. 555 BC | U10: ancient foundation date | V10: decade | W10: 2 Archaic (c. 760–481 BC) | X10: colony | Y10: Miltiades the Elder (Athenians) | Z10: colonists | AA10: Athens | AB10: unknown | AF10: IACP (Thracian Chersonese); ATL | AH10: probable | AI10: Ps.-Scymnus gives Miltiades as founder of Krithote and Paktye. The site is placed only approximately. | AJ10: IACP (Thracian Chersonese); Ps.-Scymnus 705-708; Pleiades 501485 | AK10: 501485 | AL10: Athenian foundation of Miltiades the Elder, c. 560-550 BC (Ps.-Scymnus) | AO10: Site unlocated; no evidence either way. | AP10: Pleiades 501485 | AQ10: high
A11: 10 | B11: C010 | C11: Thrace | D11: Thrace | E11: Callipolis | F11: Καλλίπολις | G11: Kallioupolis (medieval Roman); Gallipoli (Italian/Western) | H11: Gelibolu | I11: city/town on site | J11: Gelibolu (Gelibolu, Çanakkale) | K11: Çanakkale | L11: Marmara | M11: Gelibolu | O11: Greek name | P11: 40.4139 | Q11: 26.6808 | R11: secure | S11: -200 | T11: c. 200 BC | U11: first attestation as Greek city | V11: decade | W11: 4 Hellenistic (334–31 BC) | X11: Greek town grown into city | Y11: unknown | Z11: none (native town) | AB11: unknown | AF11: Hierocles (Europa); bishops 431, 536, 787; Latin see from 1208; medieval Roman naval base | AH11: secure | AI11: Pleiades says it was 'founded by the Macedonians in the 5th c. BC', a claim with no clear source. It is not in IACP. It was taken by the Ottomans in 1354, their first base in Europe. | AJ11: Pleiades 501450; TIB 12 (Külzer 2008); Wikipedia: Gelibolu | AK11: 501450 | AL11: first attested 200 BC, surrendering to Philip V with Madytos (Livy 31.16.5); bishop 431 | AN11: Greek | AO11: No excavation of early levels at Gelibolu; Pleiades' 'founded by the Macedonians in the 5th c.' is unsourced, and no native predecessor is recorded. | AP11: Pleiades 501450 | AQ11: medium
A12: 11 | B12: C011 | C12: Thrace | D12: Thrace | E12: Pactya | F12: Πακτύη | G12: Paktye | I12: lost/unlocated | J12: c. 3 km S of Bolayır (Gelibolu, Çanakkale) | K12: Çanakkale | L12: Marmara | P12: 40.4854 | Q12: 26.7807 | R12: approximate | S12: -555 | T12: c. 555 BC | U12: ancient foundation date | V12: decade | W12: 2 Archaic (c. 760–481 BC) | X12: colony | Y12: Miltiades the Elder (Athenians) | Z12: colonists | AA12: Athens | AB12: unknown | AF12: IACP pp. 907-908; ATL | AH12: secure | AI12: It marked the Propontic end of Miltiades' wall across the isthmus from Kardia (Hdt. 6.36). Pliny says it was later merged into Lysimacheia. | AJ12: IACP pp. 907-908; Hdt. 6.36; Pleiades 501546; Wikipedia: Pactya | AK12: 501546 | AL12: Athenian foundation of Miltiades the Elder, c. 560-550 BC | AO12: Bektaş (2025) places Paktye at Maltepe Höyük near Bolayır. The 'höyük' name suggests a mound, but no pre-Greek levels have been published. | AP12: Bektaş, Anadolu Araştırmaları 32 (2025) 138-176; Pleiades 501546; Hdt. 6.36 | AQ12: low
A13: 12 | B13: C012 | C13: Thrace | D13: Thrace | E13: Agora | F13: Ἀγορά | G13: Chersonesos (city of the Chersonesitai) | I13: lost/unlocated | J13: near Bolayır (Gelibolu, Çanakkale) | K13: Çanakkale | L13: Marmara | P13: 40.5135 | Q13: 26.7864 | R13: approximate | S13: -560 | T13: c. 560 BC | U13: ancient foundation date | V13: decade | W13: 2 Archaic (c. 760–481 BC) | X13: colony | Y13: Miltiades the Elder (Athenians) | Z13: colonists | AA13: Athens | AB13: unknown | AF13: IACP p. 905; Hdt. 7.58; ATL (Chersonesitai); lion-type 'ΧΕΡ' coinage (4th c. BC) probably of the Chersonesite state | AH13: probable | AI13: It may be the 'Chersonesos' of the sources; the site is only tentatively placed near Bolayır. A medieval Roman see 'Chersonesos' (Europa) may continue the name, but this is uncertain. | AJ13: IACP p. 905; Hdt. 7.58; Pleiades 501332; Wikipedia: Agora (Thrace) | AK13: 501332 | AL13: Athenian colony under Miltiades the Elder, c. 561-556 BC | AO13: Bektaş (2025) identifies Agora with Bolayır, where surface pottery 'from the Bronze Age' onward is reported (jointly with Bakla Burnu), but there is no site-specific publication; earlier Pleiades placement only tentative. | AP13: Bektaş, Anadolu Araştırmaları 32 (2025); Koçel Erdem 2023 (Thrace through the Ages); Pleiades 501332 | AQ13: low
A14: 13 | B14: C013 | C14: Thrace | D14: Thrace | E14: Cardia | F14: Καρδία | G14: Kardia | I14: lost/unlocated | J14: head of the Gulf of Saros near Bolayır (Gelibolu, Çanakkale) | K14: Çanakkale | L14: Marmara | P14: 40.5482 | Q14: 26.7508 | R14: approximate | S14: -650 | T14: c. 650 BC | U14: ancient foundation date | V14: century | W14: 2 Archaic (c. 760–481 BC) | X14: colony | Y14: Milesians and Klazomenians (oikist Hermochares, local tradition); later Athenians | Z14: colonists | AA14: Miletus and Klazomenai | AB14: unknown | AF14: IACP (Thracian Chersonese); Hdt. 6.33, 6.36, 7.58; own coins 4th c. BC | AH14: secure | AI14: It was the home of Eumenes and Hieronymus of Kardia. Lysimachus destroyed it c. 309 BC and moved its people to Lysimacheia. Pleiades 501458 combines Kardia and Lysimacheia, so the coordinates are approximate. | AJ14: IACP (Thracian Chersonese); Ps.-Scymnus 699-701; Hdt. 6.36; Pleiades 501458 | AK14: 501458 | AL14: Milesian-Klazomenian colony, probably 7th c. BC; Athenian settlers under Miltiades c. 560 BC | AO14: Located by recent survey at Bakla Burnu. Surface pottery 'from the Bronze Age to the Byzantine period' is reported from Bakla Burnu and Bolayır together, without detail per site, so pre-Greek occupation at Kardia itself is not established. | AP14: Koçel Erdem 2023 (Thrace through the Ages, Archaeopress) citing Bektaş 2021; Bektaş, Anadolu Araştırmaları 32 (2025); Pleiades 501458 | AQ14: low
A15: 14 | B15: C014 | C15: Thrace | D15: Thrace | E15: Lysimachia | F15: Λυσιμάχεια | G15: Hexamilion (medieval Roman fortress and see); Eksemil (Ottoman) | I15: ruins only | J15: Ortaköy / Eksemil near Bolayır (Gelibolu, Çanakkale) | K15: Çanakkale | L15: Marmara | P15: 40.583 | Q15: 26.883 | R15: approximate | S15: -309 | T15: 309 BC | U15: documented royal/imperial foundation | V15: year | W15: 4 Hellenistic (334–31 BC) | X15: royal foundation | Y15: Lysimachus | Z15: Successors | AB15: unknown | AF15: Diodorus 20.29; Lysimachus' capital; coins 3rd-2nd c. BC; refounded by Antiochus III 196 BC; see of Hexamilion (bishop 787) | AH15: secure | AI15: The site was formerly placed at Hexamili; it is now placed near Bolayır, with most ruins at Ortaköy. The medieval Roman see 'Hexamilion' (787) is taken as its continuation (seed row 'Hexamilion' merged here). | AJ15: Diod. 20.29; Livy 33.38-41; Cohen 1995; Pleiades 501458; Wikipedia: Lysimachia (Thrace) | AK15: 501458 | AL15: founded by Lysimachus in 309 BC, with the people of Kardia and other Chersonesite towns | AO15: Previously 'no known'. Ancient sources present it as Lysimachus' new city of 309 BC, with Kardia's people moved in (Paus. 1.9.8; Diod. 20.29). Recent survey work (M. H. Sayar; Bektaş 2021) treats it as a synoecism of existing Kardia (Bakla Burnu), Agora (Bolayır) and Paktye, with the city at Bolayır. Surface pottery 'from the Bronze Age to the Byzantine period' is reported from the Bolayır (Lysimacheia) and Bakla Burnu (Kardia) settlements together, so the new-ground claim no longer holds. The Bronze Age material is not published in enough detail for a 'yes'. | AP15: Paus. 1.9.8; Diod. 20.29.1; Koçel Erdem in Erdem & Şahin (eds.), Thrace through the Ages (Archaeopress 2023) ch. 1, citing Bektaş 2021 (PhD, İstanbul Univ.); Bektaş, Anadolu Araştırmaları 32 (2025) 138-176 | AQ15: low
A16: 15 | B16: C015 | C16: Thrace | D16: Thrace | E16: Aphrodisias (Thrace) | F16: Ἀφροδισιάς | G16: Colonia Flaviopolis (Roman) | I16: lost/unlocated | J16: near Bolayır (Gelibolu, Çanakkale) | K16: Çanakkale | L16: Marmara | P16: 40.5387 | Q16: 26.8346 | R16: approximate | S16: 75 | T16: c. AD 75 | U16: documented royal/imperial foundation | V16: period | W16: 5 Roman (30 BC – AD 329) | X16: Roman foundation | Y16: Flavian emperors (colonia Flaviopolis) | Z16: Roman emperors to 330 | AB16: unknown | AF16: Hierocles (Europa); Barrington 'Aphrodisias/Col. Flaviopolis' | AG16: Latin colonists in the 1st-3rd c. AD; Greek by late antiquity | AH16: uncertain | AI16: Equating the Flavian colony with Aphrodisias follows the Barrington Atlas; the site is unlocated. | AJ16: Pleiades 501352; Jones 1971, 17; RE Aphrodisias 4; Wikipedia: Aphrodisias (Thrace) | AK16: 501352 | AL16: town attested from the Hellenistic period; city status as a Flavian colonia (Flaviopolis), 1st c. AD; city in Hierocles | AO16: Site unlocated; no evidence either way. | AP16: Pleiades 501352 | AQ16: high
A17: 16 | B17: C016 | C17: Thrace | D17: Thrace | E17: Aenus | F17: Αἶνος | G17: Poltyobria / Poltymbria (earlier Thracian name, Strabo); Apsinthos (?) | H17: Enez | I17: city/town on site | J17: Enez (Enez, Edirne) | K17: Edirne | L17: Marmara | M17: Enez | O17: Greek name | P17: 40.7249 | Q17: 26.0857 | R17: secure | S17: -650 | T17: c. 650 BC | U17: ancient foundation date | V17: century | W17: 2 Archaic (c. 760–481 BC) | X17: colony | Y17: Aeolians from Mytilene and Kyme | Z17: colonists | AA17: Mytilene and Kyme | AB17: yes | AC17: text | AE17: Strabo (7 fr.) gives the earlier name Poltyobria, a Thracian name preserved only in Greek, so it is not entered as a pre-Greek name. The Apsinthian Thracians held the region. | AF17: IACP (Ainos); Hdt. 7.58; abundant Classical coinage; Hierocles (Rhodope); bishops 451, 553; autocephalous archbishopric; Gattilusi lordship 1384-1456 | AH17: secure | AI17: It lies on the E (Turkish) bank of the Hebrus mouth. The Ottomans took it in 1456. | AJ17: IACP (Ainos); Hdt. 7.58; Pleiades 501337; TIB 6 (Soustal 1991); Wikipedia: Aenus | AK17: 501337 | AL17: Aeolian colony, 7th c. BC (from Mytilene and Kyme; Alopekonnesians also named) | AN17: Greek
A18: 17 | B18: C017 | C18: Thrace | D18: Thrace | E18: Cypsela | F18: Κύψελα | G18: Kypsela; Ipsala (Ottoman) | H18: İpsala | I18: city/town on site | J18: İpsala (İpsala, Edirne) | K18: Edirne | L18: Marmara | M18: İpsala | O18: Greek name | P18: 40.9245 | Q18: 26.3921 | R18: secure | S18: -400 | T18: c. 400 BC | U18: first attestation as Greek city | V18: century | W18: 3 Classical (480–335 BC) | X18: Hellenized native town | Z18: none (native town) | AB18: yes | AC18: text | AE18: A Thracian town before it issued Greek coins; no native-script name exists. | AF18: IACP (cited, Thrace); own coins 5th-4th c. BC; Livy (Macedonian/Seleucid campaigns); Via Egnatia station; bishops 553, 787 (Rhodope) | AG18: Thracian was probably still widely spoken until the Roman period (uncertain) | AH18: probable | AI18: The name has the form of the Greek word κυψέλη ('beehive'), possibly a reinterpretation of a Thracian name. It is unclear when it became a polis; the coinage is the earliest evidence. | AJ18: IACP (Thrace); Pleiades 501489; TIB 6 (Soustal 1991); Wikipedia: Kypsela (Thrace) | AK18: 501489 | AL18: Thracian town with its own coinage with Greek legend (ΚΥΨΕ), c. 400 BC | AN18: Greek
A19: 18 | B19: C018 | C19: Thrace | D19: Thrace | E19: Peristasis | F19: Περίστασις | G19: Tiristasis (Roman itineraries); possibly Tyrodiza (Hdt. 7.25) | H19: Şarköy | I19: city/town on site | J19: Şarköy (Şarköy, Tekirdağ) | K19: Tekirdağ | L19: Marmara | M19: Şarköy | O19: unrelated | P19: 40.6177 | Q19: 27.1141 | R19: secure | S19: 1170 | T19: c. 1170 | U19: first attestation as Greek city | V19: decade | W19: 6 Roman, from Constantinople (330–1461) | X19: Greek town grown into city | Z19: none (native town) | AB19: unknown | AF19: medieval Roman bishopric by 1170 (suffragan of Herakleia) | AH19: probable | AI19: Pleiades equates Roman Tiristasis with Herodotus' Tyrodiza, a dependent town of Perinthos. Whether Classical Tyrodiza had polis status (IACP) is unverified. | AJ19: Pleiades 511449; TIB 12 (Külzer 2008); Wikipedia: Mürefte (diocese history) | AK19: 511449 | AL19: bishopric attested by 1170 (later Peristasis and Myriophyton) | AO19: Identification with Tyrodiza (Hdt. 7.25) via Pleiades; no excavation at Şarköy and no native predecessor recorded. | AP19: Pleiades 511449 | AQ19: medium
A20: 19 | B20: C019 | C20: Thrace | D20: Thrace | E20: Ganus | F20: Γάνος | G20: Serreion Teichos (Classical; identification probable); Gannos (Hierocles) | H20: Gaziköy | I20: village on site | J20: Gaziköy (Şarköy, Tekirdağ) | K20: Tekirdağ | L20: Marmara | O20: unrelated | P20: 40.7505 | Q20: 27.3244 | R20: secure | S20: -428 | T20: c. 428 BC | U20: first attestation as Greek city | V20: decade | W20: 3 Classical (480–335 BC) | X20: colony | Y20: unknown Greek settlers (legend: companions of Byzas) | Z20: colonists | AB20: unknown | AF20: IACP p. 922 (Serreion Teichos); ATL; Hierocles 633.1 (Gannos); bishopric, archbishopric 1324, metropolis 1329 | AH20: probable | AI20: Equating Serreion Teichos with Ganos follows Pleiades and the Barrington Atlas. Mount Ganos was a major medieval Roman monastic and wine centre. The mother city is unrecorded. | AJ20: IACP p. 922; ATL I 545-46; Pleiades 511415; Wikipedia: Ganos; TIB 12 | AK20: 511415 | AL20: as Serreion Teichos, a tribute-paying Greek community 428/7-418/7 BC (ATL); Ganos a fort by the 4th c. BC; city in Hierocles | AO20: Ganos was a stronghold of the Odrysian kings in the 4th c. BC (Aeschin. 2.90, 3.82) and one of the coastal places Seuthes offered Xenophon (Anab. 7.5.8), but nothing shows a native settlement before the Greek community. The Ganos survey (Işıklar Dağı) has published Classical and later pottery and an Iron Age-to-Roman cult place, with no pre-Greek settlement levels. | AP20: Aeschin. 2.90, 3.82; Xen. Anab. 7.5.8; Şahin and Bülbül in Thrace through the Ages (Archaeopress 2023); Pleiades 511415 | AQ20: low
A21: 20 | B21: C020 | C21: Thrace | D21: Thrace | E21: Orni | F21: Ὄρνοι | G21: Ornoi; Ornos (Nepos) | I21: lost/unlocated | J21: S of İnecik (Süleymanpaşa, Tekirdağ) | K21: Tekirdağ | L21: Marmara | P21: 40.9143 | Q21: 27.2803 | R21: approximate | S21: 527 | T21: c. AD 527 | U21: first attestation as Greek city | V21: century | W21: 6 Roman, from Constantinople (330–1461) | X21: Greek town grown into city | Z21: none (native town) | AB21: unknown | AF21: Hierocles 632.6 (Europa); Nepos, Alc. 7.4 | AH21: probable | AI21: C. Foss (Barrington Atlas) places it tentatively S of İnecik. | AJ21: Hierocles 632.6; Nepos, Alcibiades 7.4; Pleiades 511347 | AK21: 511347 | AL21: city in Hierocles (c. 527); earlier a fortified place of Alcibiades (c. 405 BC) | AO21: Site unlocated; no evidence either way. | AP21: Pleiades 511347 | AQ21: high
A22: 21 | B22: C021 | C22: Thrace | D22: Thrace | E22: Apri | F22: Ἄπρος | G22: Aproi; Colonia Claudia Aprensis; Theodosiopolis (Theodosius I or II); Naples (Frankish) | H22: Kermeyan | I22: village on site | J22: Kermeyan (Malkara, Tekirdağ) | K22: Tekirdağ | L22: Marmara | O22: unrelated | P22: 40.9269 | Q22: 27.1074 | R22: approximate | S22: 46 | T22: c. AD 46 | U22: documented royal/imperial foundation | V22: decade | W22: 5 Roman (30 BC – AD 329) | X22: Roman foundation | Y22: Claudius | Z22: Roman emperors to 330 | AB22: yes | AC22: archaeology | AF22: Pliny NH 4.47 (colonia); Ptolemy; Hierocles (Europa); bishops 431 (council list), 458, 536, 787, 878; archbishopric by 640, metropolis 1179 | AG22: Latin-speaking veteran colony at first; Greek-speaking by late antiquity | AH22: secure | AI22: The site at Kermeyan follows the Barrington Atlas/Pleiades; the council seed placed it at Malkara. The Bulgarians destroyed it in 1205. | AJ22: Pleiades 511153; Pliny NH 4.47; Catholic Encyclopedia: Theodosiopolis; TIB 12 | AK22: 511153 | AL22: Roman colony founded by Claudius (Colonia Claudia Aprensis), c. AD 46-54 | AO22: Apros existed before the Claudian veteran colony: Theopompus (4th c. BC, cited by Steph. Byz.) names it, and the name is Thracian. The colony (Colonia Claudia Aprensis) took the name of this inland Thracian town. This is a refoundation of a native town on textual grounds; no pre-Roman levels have been reported at Kermeyan. | AP22: Steph. Byz. s.v. Ἄπρος (Theopompus); Plin. NH 4.47; en.wikipedia.org/wiki/Aproi; Pleiades 511153 | AQ22: low
A23: 22 | B23: C022 | C23: Thrace | D23: Thrace | E23: Panium | F23: Πάνιον | G23: Paniai (Classical); Theodosiopolis (late 4th/5th c.); Panidos | H23: Barbaros | I23: village on site | J23: Barbaros (Süleymanpaşa, Tekirdağ) | K23: Tekirdağ | L23: Marmara | O23: unrelated | P23: 40.9071 | Q23: 27.467 | R23: secure | S23: 400 | T23: c. AD 400 | U23: first attestation as Greek city | V23: period | W23: 6 Roman, from Constantinople (330–1461) | X23: Greek town grown into city | Z23: none (native town) | AB23: unknown | AF23: Hierocles (Europa); bishops 536, 680, 787, 14th c. | AH23: secure | AI23: Pleiades records a Classical settlement 'Paniai', whose status is unknown. Some Turkish scholars place Bisanthe at Barbaros instead. Home of the historian Priscus of Panium. | AJ23: Pleiades 511351; Wikipedia: Panion; Jones 1971, 381 n. 37; TIB 12 | AK23: 511351 | AL23: walls restored 383-403 and renamed Theodosiopolis; city in Hierocles; bishop 536 | AO23: At Barbaros, surveys found Classical (5th c. BC) black-glaze pottery and 4th c. BC Greek inscriptions; no pre-Greek levels reported. | AP23: kureansiklopedi.com/tr/detay/bisanthe-barbaros-yerlesim-alani-d5bd0; Pleiades 511351 | AQ23: medium
A24: 23 | B24: C023 | C24: Thrace | D24: Thrace | E24: Bisanthe | F24: Βισάνθη | G24: Rhaidestos / Rhaedestus (from Roman times); Rodosto / Rodoscuk (Ottoman) | H24: Tekirdağ | I24: city/town on site | J24: Tekirdağ (Süleymanpaşa, Tekirdağ) | K24: Tekirdağ | L24: Marmara | M24: Süleymanpaşa | N24: yes | O24: unrelated | P24: 40.9784 | Q24: 27.508 | R24: approximate | S24: -600 | T24: c. 600 BC | U24: ancient foundation date | V24: century | W24: 2 Archaic (c. 760–481 BC) | X24: colony | Y24: Samians | Z24: colonists | AA24: Samos | AB24: unknown | AF24: IACP (Propontic Thrace); Hdt. 7.137; Xen. Anab. 7 (offered by Seuthes); ATL; bishopric Rhaidestos (787), later metropolis | AH24: probable | AI24: Equating Bisanthe with Rhaidestos (Tekirdağ) follows Pleiades/Barrington; some Turkish scholars put Bisanthe at Barbaros. The Ottoman name Rodosto continues Rhaidestos; Tekirdağ is a separate Turkish name. | AJ24: IACP (Propontic Thrace); Hdt. 7.137; Pleiades 511187; TIB 12 (Külzer 2008) | AK24: 511187 | AL24: Samian colony, Archaic (c. 600 BC; the Samian Propontic colonies date from c. 600) | AO24: TDV İslâm Ansiklopedisi suggests that Thracians (Bistones) first settled the site and that the name Bisanthe is Thracian, but this is inference; no pre-Greek levels have been reported at Tekirdağ (finds there are 4th c. BC Thracian gravestones). | AP24: islamansiklopedisi.org.tr/tekirdag; Hdt. 7.137; Pleiades 511187 | AQ24: low
A25: 24 | B25: C024 | C25: Thrace | D25: Thrace | E25: Heraeum (Heraion Teichos) | F25: Ἡραῖον τεῖχος | G25: Hieron/Hiereum, Ereon (itineraries) | I25: lost/unlocated | J25: coast E of Tekirdağ (Süleymanpaşa, Tekirdağ), exact site unknown | K25: Tekirdağ | L25: Marmara | P25: 41.0048 | Q25: 27.6896 | R25: approximate | S25: -600 | T25: c. 600 BC | U25: ancient foundation date | V25: century | W25: 2 Archaic (c. 760–481 BC) | X25: colony | Y25: Samians | Z25: colonists | AA25: Samos | AB25: unknown | AF25: IACP p. 918; besieged by Philip II 352 BC (Dem. 3.4) | AH25: probable | AI25: It lay a little E of Bisanthe; the site is not identified (Wikipedia gives c. 41.02 N 27.74 E). | AJ25: IACP p. 918; Suda / Harpokration s.v.; Pleiades 511271; Wikipedia: Heraion Teichos | AK25: 511271 | AL25: Samian colony c. 600 BC | AO25: Rejected the proposed 'yes'. The only source is the Turkish excavator's own summary (N. Atik, Arkeoloji ve Sanat 152, 2016). It calls Karaevlialtı a 'Thracian settlement mound' whose 'earliest finds were terracotta pieces dating back to 3000 BC', but the earliest architecture is 6th c. BC, and it reports no stratified pre-colonial level. Menekşe Çatağı is only 'nearby' (rule 8), and kureansiklopedi does not count. No non-Turkish corroboration found; the IACP and Barrington give no prehistoric data, and Barrington places Heraion at 'Aytepe'. This could become 'yes' if the KST reports show a stratified EBA level under the acropolis. | AP25: Atik 2016, record and abstract at acikerisim.nku.edu.tr/xmlui/handle/20.500.11776/6787; en.wikipedia.org/wiki/Heraion_Teichos (IACP p. 918; Hdt. 4.90); Pleiades 511271 | AQ25: low
A26: 25 | B26: C025 | C26: Thrace | D26: Thrace | E26: Perinthus | F26: Πέρινθος | G26: Herakleia / Heraclea (Thraciae), from the 3rd c. AD | H26: Marmaraereğlisi | I26: city/town on site | J26: Marmara Ereğlisi (Marmaraereğlisi, Tekirdağ) | K26: Tekirdağ | L26: Marmara | M26: Marmaraereğlisi | O26: Greek name | P26: 40.971 | Q26: 27.953 | R26: secure | S26: -602 | T26: 602 BC | U26: ancient foundation date | V26: year | W26: 2 Archaic (c. 760–481 BC) | X26: colony | Y26: Samians | Z26: colonists | AA26: Samos | AB26: unknown | AF26: IACP (Propontic Thrace); ATL; coins; Roman neokoros city and capital of Thracia; Hierocles (Europa; metropolis); bishops from 325 | AH26: secure | AI26: Turkish Ereğli comes from Herakleia, not Perinthos. Philip II besieged it in 340 BC. | AJ26: IACP (Propontic Thrace); Sayar 1998; Pleiades 511357; TIB 12 | AK26: 511357 | AL26: Samian colony, 602/1 BC (Eusebius/Jerome) | AN26: Greek | AO26: Rejected the proposed 'yes'. The Bronze Age claim rests only on press reports (Milliyet 2022; turkisharchaeonews/Hürriyet Nov. 2021: 'ceramics, spoon pieces, cooking utensils and animal bones believed to be 5,000 years old'). These announce unpublished finds from the Koçel Erdem excavations, with no stratigraphy or exact findspot (rule 4). The early name 'Mygdonia' comes only from Tzetzes, a late source and not a good one (rule 6). The standard works (Sayar 1998; Schönert-Geiß 1965; BNP) report no pre-Samian levels. | AP26: turkisharchaeonews.net/node/1042; en.wikipedia.org/wiki/Perinthus (Sayar 1998, 2021; von Bredow BNP); Pleiades 511357 | AQ26: medium
A27: 26 | B27: C026 | C27: Thrace | D27: Thrace | E27: Daminon Teichos | F27: Δαμίνον τεῖχος | G27: Daunion Teichos; Daunium; possibly medieval Roman see Daonion | I27: lost/unlocated | J27: near Gümüşyaka (Silivri, İstanbul) | K27: İstanbul | L27: Marmara | P27: 41.0535 | Q27: 28.0384 | R27: approximate | S27: -454 | T27: c. 454 BC | U27: first attestation as Greek city | V27: decade | W27: 3 Classical (480–335 BC) | X27: colony | Y27: unknown Greek settlers | Z27: colonists | AB27: unknown | AF27: IACP p. 918; ATL 454/3-418/7; Ps.-Skylax (between Perinthos and Selymbria) | AH27: probable | AI27: The mother city is unrecorded (probably Samian/Perinthian sphere). The medieval Roman see Daonion (suffragan of Herakleia) may be the same place, which is unverified. | AJ27: IACP p. 918; ATL; Pleiades 511227; Wikipedia: Daminon Teichos | AK27: 511227 | AL27: tribute-paying Greek community 454/3-418/7 BC (ATL) | AO27: Site unlocated (near Gümüşyaka?); no evidence either way. | AP27: Pleiades 511227 | AQ27: high
A28: 27 | B28: C027 | C28: Thrace | D28: Thrace | E28: Selymbria | F28: Σηλυμβρία | G28: Selybria; Eudoxiopolis (c. 400, after Empress Eudoxia) | H28: Silivri | I28: city/town on site | J28: Silivri (Silivri, İstanbul) | K28: İstanbul | L28: Marmara | M28: Silivri | O28: pre-Greek name | P28: 41.0785 | Q28: 28.2477 | R28: secure | S28: -670 | T28: c. 670 BC | U28: ancient foundation date | V28: century | W28: 2 Archaic (c. 760–481 BC) | X28: colony | Y28: Megarians | Z28: colonists | AA28: Megara | AB28: yes | AC28: text | AE28: The name is Thracian, 'town of Selys' (-bria = town, Strabo 7.6.1), which implies a Thracian place; it is known only through Greek, so not entered as a pre-Greek name. | AF28: IACP (Propontic Thrace); ATL; coins; Hierocles (Europa, as Eudoxiopolis); bishops 451, 680-81; archbishopric; surrendered to the Ottomans 1453 | AH28: secure | AI28: Silivri continues the Thracian name Selymbria. | AJ28: IACP (Propontic Thrace); Strabo 7.6.1; Pleiades 511414; TIB 12 | AK28: 511414 | AL28: Megarian colony, founded before Byzantium (Ps.-Scymnus), i.e. before c. 667-659 BC | AN28: Greek
A29: 28 | B29: C028 | C29: Thrace | D29: Thrace | E29: Athyras | F29: Ἀθύρας | G29: Athyra (medieval Roman see) | H29: Büyükçekmece | I29: city/town on site | J29: Büyükçekmece (Büyükçekmece, İstanbul) | K29: İstanbul | L29: Marmara | M29: Büyükçekmece | O29: unrelated | P29: 41.034 | Q29: 28.59 | R29: secure | S29: 900 | T29: c. AD 900 | U29: first attestation as Greek city | V29: century | W29: 6 Roman, from Constantinople (330–1461) | X29: Greek town grown into city | Z29: none (native town) | AB29: unknown | AF29: medieval Roman bishopric (suffragan of Herakleia), Catholic titular see Athyra | AH29: probable | AI29: The date of the first bishop is not verified; the date given is the earliest Notitia listing I could confirm. | AJ29: Pleiades 511172; TIB 12 (Külzer 2008); Le Quien, Oriens Christianus | AK29: 511172 | AL29: see of Athyra in the medieval Roman Notitiae (c. 10th c.); a settlement since the Hellenistic period | AO29: Athyras is attested in Hellenistic-Roman sources; no pre-Greek levels are reported at Büyükçekmece. | AP29: Pleiades 511172; en.wikipedia.org/wiki/Athyras | AQ29: medium
A30: 29 | B30: C029 | C30: Thrace | D30: Thrace | E30: Byzantium | F30: Βυζάντιον | G30: Constantinople / Κωνσταντινούπολις, Nova Roma (Constantine 330); Antonina / Augusta Antonina (Septimius Severus, briefly); hē Polis | H30: İstanbul | I30: city/town on site | J30: Historic peninsula, Sarayburnu acropolis (Fatih, İstanbul) | K30: İstanbul | L30: Marmara | M30: Fatih | N30: yes | O30: Greek name | P30: 41.0059 | Q30: 28.9739 | R30: secure | S30: -667 | T30: c. 667 BC | U30: ancient foundation date | V30: decade | W30: 2 Archaic (c. 760–481 BC) | X30: colony | Y30: Megarians (oikist Byzas, legend) | Z30: colonists | AA30: Megara | AB30: yes | AC30: text+archaeology | AE30: Pliny (NH 4.46) says the place was earlier called Lygos, a Thracian name known only from Latin, so not entered as a pre-Greek name. Neolithic-Chalcolithic remains exist within the later city (Yenikapı). | AF30: IACP (Propontic Thrace); ATL; coins from late 5th c. BC; Roman provincial coins; imperial capital 330-1453; patriarchate (councils 381, 553, 680-81) | AH30: secure | AI30: One entry for Byzantium and Constantinople (refoundation 330). Turkish İstanbul comes from Greek εἰς τὴν Πόλιν. The Ottomans took it in 1453. Justinian's 'city' of Sykai/Ioustinianai (later Galata) is treated as part of it. | AJ30: IACP (Byzantion); Hdt. 4.144; Pliny NH 4.46; Pleiades 520985 / 520998 | AK30: 520985 | AL30: Megarian colony, c. 668-659 BC (Hdt. 4.144: 17 years after Chalcedon; Eusebius 659/8); Greek pottery from the 7th c. BC | AN30: Greek
A31: 30 | B31: C030 | C31: Thrace | D31: Thrace | E31: Metrae | F31: Μέτραι | G31: Metrai | H31: Çatalca | I31: city/town on site | J31: Çatalca (Çatalca, İstanbul) | K31: İstanbul | L31: Marmara | M31: Çatalca | O31: unrelated | P31: 41.143 | Q31: 28.462 | R31: approximate | S31: 787 | T31: AD 787 | U31: first attestation as Greek city | V31: year | W31: 6 Roman, from Constantinople (330–1461) | X31: Greek town grown into city | Z31: none (native town) | AB31: unknown | AF31: bishop 787; suffragan of Herakleia (still listed in modern times) | AH31: probable | AI31: Identification with Çatalca is the modern view given in the council seed. | AJ31: Council seed (Nicaea 787); TIB 12 (Külzer 2008); Catholic Encyclopedia: Heraclea | AL31: first bishop at Nicaea II (787) | AO31: Identification with Çatalca rests on the council seed; no excavation and no native predecessor recorded. | AQ31: high
A32: 31 | B32: C031 | C32: Thrace | D32: Thrace | E32: Dercos | F32: Δέρκος | G32: Delkos; Terkos (Ottoman) | H32: Durusu | I32: village on site | J32: Durusu (Arnavutköy, İstanbul) | K32: İstanbul | L32: Marmara | O32: unrelated | P32: 41.2999 | Q32: 28.6784 | R32: approximate | S32: 787 | T32: AD 787 | U32: first attestation as Greek city | V32: year | W32: 6 Roman, from Constantinople (330–1461) | X32: Greek town grown into city | Z32: none (native town) | AB32: unknown | AF32: bishop 787; later archbishopric and metropolis of Derkos | AH32: probable | AI32: It was a Roman station (Delkos); Durusu was called Terkos until the 20th c. The council seed point lies c. 9 km from Durusu; the Pleiades point is used here. | AJ32: Pleiades 511231; Council seed (Nicaea 787); TIB 12 | AK32: 511231 | AL32: first bishop at Nicaea II (787); later archbishopric/metropolis | AO32: In antiquity a village (Delkos) in Byzantion's territory by the lagoon; no earlier settlement reported at Durusu. | AP32: Pleiades 511231; thebyzantinelegacy.com/derkos | AQ32: medium
A33: 32 | B33: C032 | C33: Thrace | D33: Thrace | E33: Medea | F33: Μήδεια | G33: Salmydessos (Thracian coast and town); Midye (Ottoman) | H33: Kıyıköy | I33: village on site | J33: Kıyıköy (Vize, Kırklareli) | K33: Kırklareli | L33: Marmara | O33: unrelated | P33: 41.6348 | Q33: 28.0957 | R33: secure | S33: 900 | T33: c. AD 900 | U33: first attestation as Greek city | V33: century | W33: 6 Roman, from Constantinople (330–1461) | X33: Greek town grown into city | Z33: none (native town) | AB33: yes | AC33: text | AE33: Salmydessos was a coast and town of the Thracian Thynoi (Hdt. 4.93; Xen. Anab. 7.5); no native-script name. | AF33: medieval Roman archbishopric, later metropolis; Catholic titular see Medea; Justinianic fortifications | AH33: probable | AI33: The medieval Roman name Medeia continues in Midye. The date of the first see is not exactly verified. It submitted to the Ottomans in 1453. | AJ33: Pleiades 511404; TIB 12 (Külzer 2008); Wikipedia: Kıyıköy | AK33: 511404 | AL33: walls built under Justinian; archbishopric (later metropolis) in the Notitiae from c. 900
A34: 33 | B34: C033 | C34: Thrace | D34: Thrace | E34: Bizye | F34: Βιζύη | G34: Vize | H34: Vize | I34: city/town on site | J34: Vize (Vize, Kırklareli) | K34: Kırklareli | L34: Marmara | M34: Vize | O34: pre-Greek name | P34: 41.5727 | Q34: 27.7653 | R34: secure | S34: 117 | T34: c. AD 117 | U34: first attestation as Greek city | V34: period | W34: 5 Roman (30 BC – AD 329) | X34: Hellenized native town | Z34: none (native town) | AB34: yes | AC34: text+archaeology | AE34: Thracian royal residence (Pliny: 'arx regum Thraciae'); Thracian royal tumuli at Vize; the name is Thracian but has no native-script attestation. | AF34: Roman provincial coins; Hierocles (Europa); bishops 431-787; autocephalous archbishopric; Hagia Sophia church | AH34: secure | AI34: The Thracian kings used Greek in their inscriptions before AD 46. The start date of the coinage (Trajan or Hadrian) is approximate. | AJ34: Pleiades 511190; Pliny NH 4.47; Jones 1971; TIB 12 | AK34: 511190 | AL34: civic coins with Greek legends from the 2nd c. AD (Hadrian to Philip); earlier the seat of the Thracian (Astaean) kings, 1st c. BC-AD 46 | AN34: Greek
A35: 34 | B35: C034 | C35: Thrace | D35: Thrace | E35: Brysis | F35: Βρύσις | G35: Verissa (Latin archbishopric 1204-) | H35: Pınarhisar | I35: city/town on site | J35: Pınarhisar (Pınarhisar, Kırklareli) | K35: Kırklareli | L35: Marmara | M35: Pınarhisar | O35: unrelated | P35: 41.6253 | Q35: 27.5197 | R35: secure | S35: 787 | T35: AD 787 | U35: first attestation as Greek city | V35: year | W35: 6 Roman, from Constantinople (330–1461) | X35: Greek town grown into city | Z35: none (native town) | AB35: unknown | AF35: bishops 787, 879, 1027, 1315-31; archbishopric in Notitia of Leo VI | AH35: probable | AI35: Turkish Pınar ('spring') translates Greek βρύσις. Turkish sources say it was founded under Theodosius II, which is unverified. The Ottomans took it in 1368. | AJ35: Wikipedia: Pınarhisar; TIB 12 (Külzer 2008); Le Quien, Oriens Christianus | AL35: archbishop John at Nicaea II (787) | AO35: Turkish sources date the town to Theodosius II; the castle is early Byzantine and no Thracian or earlier settlement is reported at Pınarhisar. | AP35: en.wikipedia.org/wiki/Brysis; castles.nl/pinarhisar-castle | AQ35: medium
A36: 35 | B36: C035 | C36: Thrace | D36: Thrace | E36: Tzurulum | F36: Τζουρουλός | G36: Tzirallum (Lactantius); Tyroloe; Zorolus (titular see) | H36: Çorlu | I36: city/town on site | J36: Çorlu (Çorlu, Tekirdağ) | K36: Tekirdağ | L36: Marmara | M36: Çorlu | O36: pre-Greek name | P36: 41.1667 | Q36: 27.7954 | R36: secure | S36: 787 | T36: AD 787 | U36: first attestation as Greek city | V36: year | W36: 6 Roman, from Constantinople (330–1461) | X36: Hellenized native town | Z36: none (native town) | AB36: yes | AC36: text | AE36: The name is probably Thracian (Tzirallum/Syrallum), known only from Latin and Greek sources. | AF36: bishop 787; later metropolis; major medieval Roman fortress town (Pecheneg siege 1090) | AH36: probable | AI36: The Thracian origin of the name is likely but unproven. The Ottomans took it in the 1350s/60s under Murad I. | AJ36: Pleiades 511456; Council seed (Nicaea 787); TIB 12 | AK36: 511456 | AL36: Roman station (Tzirallum, 313); fortified by Justinian; first bishop at Nicaea II (787) | AN36: Greek
A37: 36 | B37: C036 | C37: Thrace | D37: Thrace | E37: Drizipara | F37: Δριζίπαρα | G37: Drousipara / Drusipara; Mesene (from the 9th c.) | H37: Misinli | I37: village on site | J37: Misinli near Büyükkarıştıran (Lüleburgaz, Kırklareli) | K37: Kırklareli | L37: Marmara | O37: Greek name | P37: 41.3001 | Q37: 27.544 | R37: secure | S37: 553 | T37: AD 553 | U37: first attestation as Greek city | V37: year | W37: 6 Roman, from Constantinople (330–1461) | X37: Hellenized native town | Z37: none (native town) | AB37: yes | AC37: text | AE37: Thracian name (-para 'village'), known only from Greek and Latin sources. | AF37: bishops 553, 787; later autocephalous archbishopric (as Mesene); shrine of St Alexander | AH37: secure | AI37: The see may date from the 4th c., but 553 is the first certain bishop. The Avars sacked it in 591. Misinli continues the medieval name Mesene. | AJ37: Pleiades 511241; Wikipedia: Drizipara; TIB 12 | AK37: 511241 | AL37: Thracian-named town (Ptolemy, itineraries); first bishop attested 553 | AN37: Greek
A38: 37 | B38: C037 | C38: Thrace | D38: Thrace | E38: Chariopolis | F38: Χαριούπολις | G38: Charioupolis | H38: Hayrabolu | I38: city/town on site | J38: Hayrabolu (Hayrabolu, Tekirdağ) | K38: Tekirdağ | L38: Marmara | M38: Hayrabolu | O38: Greek name | P38: 41.2141 | Q38: 27.1056 | R38: secure | S38: 787 | T38: AD 787 | U38: first attestation as Greek city | V38: year | W38: 6 Roman, from Constantinople (330–1461) | X38: Greek town grown into city | Z38: none (native town) | AB38: unknown | AF38: bishops 787-1351 (suffragan of Herakleia) | AH38: probable | AI38: Nothing is known of an ancient predecessor. It was sacked by the Pechenegs in 1087. | AJ38: Pleiades 511206; Catholic Encyclopedia: Chariopolis; TIB 12 | AK38: 511206 | AL38: first bishop at Nicaea II (787) | AN38: Greek | AO38: Nothing is known of an ancient predecessor at Hayrabolu; the district has Thracian dolmens and tumuli, but no settlement under the town is reported. | AP38: en.wikipedia.org/wiki/Hayrabolu; Pleiades 511206 | AQ38: medium
A39: 38 | B39: C038 | C39: Thrace | D39: Thrace | E39: Arcadiopolis | F39: Ἀρκαδιούπολις | G39: Bergule / Bergoule (Thracian town) | H39: Lüleburgaz | I39: city/town on site | J39: Lüleburgaz (Lüleburgaz, Kırklareli) | K39: Kırklareli | L39: Marmara | M39: Lüleburgaz | O39: unrelated | P39: 41.4017 | Q39: 27.3527 | R39: secure | S39: 395 | T39: c. AD 395 | U39: documented royal/imperial foundation | V39: decade | W39: 6 Roman, from Constantinople (330–1461) | X39: Roman foundation | Y39: Theodosius I or Arcadius | Z39: emperors in Constantinople 330–1461 | AB39: yes | AC39: text | AE39: Bergule, a town of the Thracian Astai (Ptolemy, itineraries); the name has no native-script attestation. | AF39: Hierocles (Europa); bishops 553, 787; archbishopric | AH39: secure | AI39: It was briefly the capital of Europa. The medieval Romans defeated the Rus' here in 970. | AJ39: Pleiades 511185; TIB 12 (Külzer 2008); Wikipedia: Lüleburgaz | AK39: 511185 | AL39: Thracian Bergule raised to city status and renamed for Arcadius by Theodosius I (or Arcadius), c. 390s
A40: 39 | B40: C039 | C40: Thrace | D40: Thrace | E40: Bulgarophygon | F40: Βουλγαρόφυγον | G40: Bourtoudizos / Burtudizon (Roman station); Arteskos (later Greek) | H40: Babaeski | I40: city/town on site | J40: Babaeski (Babaeski, Kırklareli) | K40: Kırklareli | L40: Marmara | M40: Babaeski | O40: unrelated | P40: 41.4279 | Q40: 27.0924 | R40: secure | S40: 787 | T40: AD 787 | U40: first attestation as Greek city | V40: year | W40: 6 Roman, from Constantinople (330–1461) | X40: Hellenized native town | Z40: none (native town) | AB40: yes | AC40: text | AE40: Roman station Burtudizon/Bourdizos with a Thracian name; no native-script attestation. | AF40: bishop 787 (council seed); see in the Notitiae; Catholic titular see Bulgarophygum | AH40: probable | AI40: The council seed records a bishop in 787; the name Bulgarophygon is otherwise first known from the battle of 896. | AJ40: Pleiades 511195; Council seed (Nicaea 787); TIB 12 | AK40: 511195 | AL40: bishop at Nicaea II (787) per council list; earlier the Thracian-named station Bourtoudizos, fortified by Justinian
...

Sheet Summary
A1: Greek cities in present-day Turkey: summary (all counts are formulas on the Cities sheet)
A3: All cities | B3: =COUNTA(Cities!B2:B604) -> 603
A5: How each city became Greek | B5: Cities | C5: Share
A6: Mycenaean | B6: =COUNTIF(Cities!X2:X604,A6) -> 1 | C6: =IF($B$3=0,0,B6/$B$3) -> 0.0016583748
A7: migration | B7: =COUNTIF(Cities!X2:X604,A7) -> 34 | C7: =IF($B$3=0,0,B7/$B$3) -> 0.056384743
A8: colony | B8: =COUNTIF(Cities!X2:X604,A8) -> 84 | C8: =IF($B$3=0,0,B8/$B$3) -> 0.13930348
A9: royal foundation | B9: =COUNTIF(Cities!X2:X604,A9) -> 78 | C9: =IF($B$3=0,0,B9/$B$3) -> 0.12935323
A10: Roman foundation | B10: =COUNTIF(Cities!X2:X604,A10) -> 67 | C10: =IF($B$3=0,0,B10/$B$3) -> 0.11111111
A11: Hellenized native town | B11: =COUNTIF(Cities!X2:X604,A11) -> 247 | C11: =IF($B$3=0,0,B11/$B$3) -> 0.40961857
A12: Greek town grown into city | B12: =COUNTIF(Cities!X2:X604,A12) -> 92 | C12: =IF($B$3=0,0,B12/$B$3) -> 0.15257048
A14: Period in which it became Greek | B14: Cities | C14: Share
A15: 1 Mycenaeans and migrations (to c. 760 BC) | B15: =COUNTIF(Cities!W2:W604,A15) -> 26 | C15: =IF($B$3=0,0,B15/$B$3) -> 0.043117745
A16: 2 Archaic (c. 760–481 BC) | B16: =COUNTIF(Cities!W2:W604,A16) -> 57 | C16: =IF($B$3=0,0,B16/$B$3) -> 0.094527363
A17: 3 Classical (480–335 BC) | B17: =COUNTIF(Cities!W2:W604,A17) -> 87 | C17: =IF($B$3=0,0,B17/$B$3) -> 0.14427861
A18: 4 Hellenistic (334–31 BC) | B18: =COUNTIF(Cities!W2:W604,A18) -> 169 | C18: =IF($B$3=0,0,B18/$B$3) -> 0.28026534
A19: 5 Roman (30 BC – AD 329) | B19: =COUNTIF(Cities!W2:W604,A19) -> 157 | C19: =IF($B$3=0,0,B19/$B$3) -> 0.26036484
A20: 6 Roman, from Constantinople (330–1461) | B20: =COUNTIF(Cities!W2:W604,A20) -> 107 | C20: =IF($B$3=0,0,B20/$B$3) -> 0.1774461
A22: Present-day region | B22: Cities | C22: Share
A23: Aegean | B23: =COUNTIF(Cities!L2:L604,A23) -> 194 | C23: =IF($B$3=0,0,B23/$B$3) -> 0.32172471
A24: Mediterranean | B24: =COUNTIF(Cities!L2:L604,A24) -> 145 | C24: =IF($B$3=0,0,B24/$B$3) -> 0.24046434
A25: Marmara | B25: =COUNTIF(Cities!L2:L604,A25) -> 112 | C25: =IF($B$3=0,0,B25/$B$3) -> 0.18573798
A26: Central Anatolia | B26: =COUNTIF(Cities!L2:L604,A26) -> 75 | C26: =IF($B$3=0,0,B26/$B$3) -> 0.12437811
A27: Black Sea | B27: =COUNTIF(Cities!L2:L604,A27) -> 57 | C27: =IF($B$3=0,0,B27/$B$3) -> 0.094527363
A28: Southeastern Anatolia | B28: =COUNTIF(Cities!L2:L604,A28) -> 16 | C28: =IF($B$3=0,0,B28/$B$3) -> 0.026533997
A29: Eastern Anatolia | B29: =COUNTIF(Cities!L2:L604,A29) -> 4 | C29: =IF($B$3=0,0,B29/$B$3) -> 0.0066334992
A31: Earlier non-Greek settlement on the site | B31: Cities | C31: Share | D31: "no known" = new ground (positive evidence); "unknown" = no evidence either way.
A32: yes | B32: =COUNTIF(Cities!AB2:AB604,A32) -> 358 | C32: =IF($B$3=0,0,B32/$B$3) -> 0.59369818
A33: no known | B33: =COUNTIF(Cities!AB2:AB604,A33) -> 17 | C33: =IF($B$3=0,0,B33/$B$3) -> 0.028192371
A34: unknown | B34: =COUNTIF(Cities!AB2:AB604,A34) -> 228 | C34: =IF($B$3=0,0,B34/$B$3) -> 0.37810945
A36: Mixed cities (Greek beside Aramaic or Armenian) | B36: Cities | C36: Share
A37: yes | B37: =COUNTIF(Cities!AM2:AM604,A37) -> 18 | C37: =IF($B$3=0,0,B37/$B$3) -> 0.029850746
A39: Turkish name reached Turkish through | B39: Cities | C39: Share | D39: Only for town or village names that continue the ancient name.
A40: Greek | B40: =COUNTIF(Cities!AN2:AN604,A40) -> 85 | C40: =IF($B$3=0,0,B40/$B$3) -> 0.14096186
A41: Syriac/Arabic | B41: =COUNTIF(Cities!AN2:AN604,A41) -> 5 | C41: =IF($B$3=0,0,B41/$B$3) -> 0.008291874
A43: Modern status of the site | B43: Cities | C43: Share
A44: city/town on site | B44: =COUNTIF(Cities!I2:I604,A44) -> 157 | C44: =IF($B$3=0,0,B44/$B$3) -> 0.26036484
A45: village on site | B45: =COUNTIF(Cities!I2:I604,A45) -> 101 | C45: =IF($B$3=0,0,B45/$B$3) -> 0.16749585
A46: ruins only | B46: =COUNTIF(Cities!I2:I604,A46) -> 270 | C46: =IF($B$3=0,0,B46/$B$3) -> 0.44776119
A47: lost/unlocated | B47: =COUNTIF(Cities!I2:I604,A47) -> 75 | C47: =IF($B$3=0,0,B47/$B$3) -> 0.12437811
A49: Turkish name comes from | B49: Cities | C49: Share | D49: Only for cities with a town or village on the site.
...

Sheet Not included
A1: Place | B1: Reason | C1: Batch
A2: Oca (council seed, İnhisar, Bilecik) | B2: Misplaced: the Hellespontine see Okai is placed in the Biga district (Çanakkale, TRO batch). The epigraphic Oka near Harmanköy (İnhisar) is a village of Nicaea's territory, not a city. | C2: BIT
A3: Unnamed council seed row 40.3, 29.85 (Constantinople 553; 680–81; Nicaea 787) | B3: non-greek: Unlocatable. (eastern review, Oct 2026) | C3: BIT
A4: Unnamed council seed row 40.3, 29.8 (Ephesus 431) | B4: non-greek: Unlocatable. (eastern review, Oct 2026) | C4: BIT
A5: Unnamed council seed row 40.6, 30.2 (Nicaea 325; Constantinople 381) | B5: non-greek: Unlocatable. (eastern review, Oct 2026) | C5: BIT
A6: Daphnous (Pleiades 511222) | B6: A Hellenistic place-name in the Rhyndakos plain; village, with no civic evidence. | C6: BIT
A7: Artaiouteichos (Pleiades 511159) | B7: A fort ('wall of Artaios', Classical); not a city. | C7: BIT
A8: Apsoda (Pleiades 844863) | B8: A late-antique place-name known from Nicaea inscriptions; village, not a city. | C8: BIT
A9: 'Cenon Gallicanon' (Pleiades 844891) | B9: A Roman estate or district name; not a city. | C9: BIT
A10: Kassa (Pleiades 511288) | B10: A village known from inscriptions; not a city. | C10: BIT
A11: Geragathe (Pleiades 511259) | B11: A late-antique locality near Nicomedia (estate or suburb); not a city. | C11: BIT
A12: Baradendromia (Pleiades 511176) | B12: A village known from an inscription; not a city. | C12: BIT
... A546: Arsamosata (Haraba, Elazığ; under the Keban lake) | B546: A theme seat and Greek metropolis c. 939–1050 (seals; ODB) beside a Syriac Orthodox see, with no evidence of Greek-speaking residents. A see alone does not count, as for Tzamandos. (second look, Oct 2026) | C546: EAST3

Sheet Rules
A1: Scope | B1: Cities whose site lies in present-day Turkey (Anatolia, Eastern Thrace, Imbros, Tenedos, Hatay), from Mycenaean times to the fall of Trebizond (1461).
A2: Greek city | B2: A self-governing city or urban centre with civic status (not a village, fort, sanctuary or estate) whose people spoke Greek, or came to. Evidence: polis in the Inventory of Archaic and Classical Poleis or the Athenian tribute lists; Hellenistic foundation; Greek civic decrees or coins; city in Hierocles (c. 527); bishop’s see. The same test applies in every region, with no special rule for any area (Iosif, 11 Oct 2026); a castle or fort with a lay settlement but no see and no polis title (Tripolis/Tirebolu, Koralla) does not count.
A3: Included | B3: Greek foundations of every age (Mycenaean, migration-era, colonies, royal and Roman foundations) and native Anatolian towns that became Greek-speaking cities. Roman coloniae count, since they became Greek-speaking.
A4: Language rule | B4: Revised 11 Oct 2026 (Iosif: do not discount Greek or heterogeneous cities because of where they are). A city where Greek was one of two main languages, beside Aramaic (Syriac) or Armenian, is included and marked mixed (†), given positive evidence of a Greek-speaking community: civic Greek coins or inscriptions, Greek writers or clergy from the city, Greek settlers. Mixed: Edessa, Carrhae, Nisibis, Zeugma and neighbours; Samosata, Germanikeia, Perrhe, Amida, Satala; Theodosiopolis (Erzurum) 949–c. 1071; Keltzene (Erzincan), where Clavijo (1404) found Greeks beside Armenians. Left out where Greek was only the language of the garrison, court or officials (Dara, Constantia, the Arsameias, Ani, Mantzikert, Kars), or where a Greek see stood in a town with no evidence of Greek speakers (Tzamandos, Kamacha, Arsamosata, Paipert; Tigranocerta by Iosif's choice).
A5: Date (Greek from) | B5: When the place became a Greek city: the foundation date for Greek foundations (ancient date, or archaeological where they differ); for native towns the first Greek civic evidence (decrees, coins, polis attestation, a bishop). Renamings and refoundations do not change the date.
A6: Periods | B6: By the date: 1 to c. 760 BC; 2 c. 760–481 BC; 3 480–335 BC; 4 334–31 BC; 5 30 BC – AD 329; 6 AD 330–1461.
A7: Earlier settlement | B7: "yes" = positive evidence of a non-Greek settlement on the site or the same mound (within c. 1–2 km) before the Greek city: excavated or surveyed levels, an attested pre-Greek name, a good ancient historian, or a native town that turned Greek. "no known" = new ground, also on positive evidence (excavation or survey finding nothing earlier, or a reliable account of a foundation on an empty site). "unknown" = no evidence either way. Legends, press reports, tourism and municipal pages and the LuwianSiteAtlas do not count; claims found only in Turkish sources were checked against international scholarship (Oct 2026).
A8: Pre-Greek name | B8: Only names attested in pre-Greek sources (Hittite, Luwian, Lydian, Lycian, Carian, Assyrian, Babylonian, Aramaic, Old Persian, Armenian). "?" = doubtful identification.
A9: Turkish name | B9: The present-day town or village whose built-up area covers the ancient city; ruins near a town are "ruins only". District centres and provincial capitals refer to that town. Only cities that were Greek by 1461 count (Argyroupolis/Gümüşhane and Kydonies/Ayvalık, Greek only under the Ottomans, do not). "Comes from" judges the ultimate origin of the name; "reached Turkish through" the route: all but five came through the Greek form (Konya < Ikonion); Urfa, Harran, Nusaybin, Suruç and Maraş came through Syriac and Arabic.
A10: Research | B10: 14 research agents by groups of provinces (seeded from the council sees of earlier sets and the Pleiades gazetteer), then 5 fact-check agents (pre-Greek names; modern names, west and east; dates and origins, two halves). Second round, 11 Oct 2026: earlier settlement for all 256 foundations then marked unknown or new ground (6 agents, then 2 source-critical verifiers); a review of the north-east, east and south-east (4 agents) and of Trapezuntine towns (1 agent), which added 10 cities; a second look at the inland Pontus and the east (2 agents, with Bryer & Winfield 1985 and Clavijo opened), which added Keltzene (Erzincan, mixed) and the Chaldian sees Leri and Cheriana, and dropped Tripolis when the special Pontus rule was withdrawn.
